2025-05-20 20:23:20,893 - exception_logger - ERROR - An exception occurred
Traceback (most recent call last):
  File "C:\Users\SAHIL BARKE\AppData\Local\Temp\ipykernel_19840\307899657.py", line 14, in exception_logging
    1 / 0
    ~~^~~
ZeroDivisionError: division by zero
